Workbook
Name trades: Trades!$A$1:$AH$4837

Sheet Dashboard
A4: Total PnL | D4: Wins | G4: Loss | J4: Avg gain / trade | M4: Win Rate | P4: Total trades | T4: Top symbols by PnL
A5: =GETPIVOTDATA("gainAmount",Pivots!$N$2) -> 0 | D5: =COUNTIF(Trades!L:L,1) -> 0 | G5: =COUNTIF(Trades!L:L,0) -> 1 | J5: =GETPIVOTDATA("gainAmount",Pivots!$J$2) -> 0 | M5: =D5/P5 -> 0 | P5: =D5+G5 -> 1 | T5: Symbol | U5: PnL
T6: (blank)
T7: Grand Total
T21: Top symbols by Gain %
T22: Symbol | U22: Average of gainAmount
T23: (blank)
T24: Grand Total

Sheet Pivots
A1: Daily PnL | D1: Accumulated Profit | G1: Winning trades % | J1: Average gain / trade | N1: Total profit | P1: Total trades | R1: Long/Short
A2: Row Labels | B2: Sum of gainAmount | D2: Row Labels | E2: Sum of gainAmount | G2: Row Labels | H2: Count of id | J2: Row Labels | K2: Average of gainAmount | L2: Count of gainPercent | N2: Sum of gainAmount | P2: Row Labels | Q2: Count of id | R2: Row Labels | S2: Count of id
A3: (blank) | D3: (blank) | G3: Grand Total | H3: #DIV/0! | J3: 0 | K3: 0 | L3: 14 | N3: 0 | P3: 0 | Q3: 14 | R3: 0 | S3: 1
A4: 0 | B4: 0 | D4: 0 | E4: 0 | J4: Grand Total | K4: 0 | P4: Grand Total | Q4: 14 | R4: Grand Total | S4: 1
D5: Grand Total | E5: 0

Sheet Raw
A1: Time | B1: Position | C1: Symbol | D1: Type | E1: Volume | F1: Price | G1: S / L | H1: T / P | I1: Time | J1: Price | K1: Commission | L1: Swap | M1: Profit

Sheet Trades
A1: id | B1: entryDate | C1: exitDate | D1: type | E1: symbol | F1: entryPrice | G1: exitPrice | H1: gainAmount | I1: quantity | J1: fees | K1: gainPercent | L1: Win | M1: tradeCount | N1: entryDateTime | O1: accProfit | P1: Extra2 | Q1: Extra3 | R1: Extra4 | S1: Extra5 | T1: Extra6 | U1: Extra7 | V1: Extra8 | W1: Extra9 | X1: Extra10 | Y1: Extra11 | Z1: Extra12 | AA1: Extra13 | AB1: Extra14 | AC1: Extra15 | AD1: Extra16 | AE1: Extra17 | AF1: Extra18 | AG1: Extra19 | AH1: Extra20
A2: =Raw!B2 -> 0 | B2: =Raw!A2 -> 0 | C2: =Raw!I2 -> 0 | D2: =Raw!D2 -> 0 | E2: =Raw!C2 -> 0 | F2: =Raw!F2 -> 0 | H2: =O2+J2 -> 0 | I2: =Raw!E2 -> 0 | J2: =Raw!K2 -> 0 | K2: =H2/10000 -> 0 | L2: =IF(H2>0,"1","0") -> 0 | M2: =COUNT(Raw!M2) -> 0 | N2: =Raw!A2 -> 0 | O2: =Raw!M2+Raw!K2 -> 0 | P2: =LEFT(B2,10) -> 0
P3: =LEFT(B3,10)
P4: =LEFT(B4,10)
P5: =LEFT(B5,10)
P6: =LEFT(B6,10)
P7: =LEFT(B7,10)
P8: =LEFT(B8,10)
P9: =LEFT(B9,10)
P10: =LEFT(B10,10)
P11: =LEFT(B11,10)
P12: =LEFT(B12,10)
P13: =LEFT(B13,10)
P14: =LEFT(B14,10)
P15: =LEFT(B15,10)

Sheet Sheet1
A1: id | B1: entryDate | C1: exitDate | D1: type | E1: symbol | F1: entryPrice | G1: exitPrice | H1: gainAmount | I1: quantity | J1: fees | K1: gainPercent | L1: Win | M1: tradeCount | N1: entryDateTime | O1: exitDateTime | P1: accProfit | Q1: Extra2 | R1: Extra3 | S1: Extra4 | T1: Extra5 | U1: Extra6 | V1: Extra7 | W1: Extra8 | X1: Extra9 | Y1: Extra10 | Z1: Extra11 | AA1: Extra12 | AB1: Extra13 | AC1: Extra14 | AD1: Extra15 | AE1: Extra16 | AF1: Extra17 | AG1: Extra18 | AH1: Extra19 | AI1: Extra20
A2: 2 | B2: 0 | C2: 0 | D2: buy | E2: NAS100.raw | F2: 25748.425 | G2: 25770.69 | H2: 55.66 | I2: 0 | J2: 0 | L2: 1 | N2: 2026.01.12 17:12:32 | O2: 2026.01.12 17:58:39 | P2: 55.66
A3: 3 | B3: 0 | C3: 0 | D3: buy | E3: NAS100.raw | F3: 25772.636 | G3: 25770.69 | H3: -1.95 | I3: 0 | J3: 0 | L3: 0 | N3: 2026.01.12 17:26:30 | O3: 2026.01.12 17:58:39 | P3: -1.95
A4: 4 | B4: 0 | C4: 0 | D4: buy | E4: NAS100.raw | F4: 25755.075 | G4: 25770.69 | H4: 15.61 | I4: 0 | J4: 0 | L4: 1 | N4: 2026.01.12 17:32:21 | O4: 2026.01.12 17:58:39 | P4: 15.61
A5: 5 | B5: 0 | C5: 0 | D5: buy | E5: NAS100.raw | F5: 25736.641 | G5: 25770.69 | H5: 34.05 | I5: 0 | J5: 0 | L5: 1 | N5: 2026.01.12 17:33:50 | O5: 2026.01.12 17:58:39 | P5: 34.05
A6: 6 | B6: 0 | C6: 0 | D6: buy | E6: NAS100.raw | F6: 25761.822 | G6: 25770.69 | H6: 8.87 | I6: 0 | J6: 0 | L6: 1 | N6: 2026.01.12 17:57:30 | O6: 2026.01.12 17:58:39 | P6: 8.87
A7: 7 | B7: 0 | C7: 0 | D7: buy | E7: NAS100.raw | F7: 25761.825 | G7: 25770.69 | H7: 8.86 | I7: 0 | J7: 0 | L7: 1 | N7: 2026.01.12 17:57:30 | O7: 2026.01.12 17:58:39 | P7: 8.86

Sheet Sheet2
A1: id | B1: entryDate | C1: exitDate | D1: type | E1: symbol | F1: entryPrice | G1: exitPrice | H1: gainAmount | I1: quantity | J1: fees | K1: gainPercent | L1: Win | M1: tradeCount | N1: entryDateTime | O1: exitDateTime | P1: accProfit | Q1: Extra2 | R1: Extra3 | S1: Extra4 | T1: Extra5 | U1: Extra6 | V1: Extra7 | W1: Extra8 | X1: Extra9 | Y1: Extra10 | Z1: Extra11 | AA1: Extra12 | AB1: Extra13 | AC1: Extra14 | AD1: Extra15 | AE1: Extra16 | AF1: Extra17 | AG1: Extra18 | AH1: Extra19 | AI1: Extra20
A2: 2 | B2: 0 | C2: 0 | D2: buy | E2: NAS100.raw | F2: 25748.425 | G2: 25770.69 | H2: 55.66 | I2: 0 | J2: 0 | L2: 1 | N2: 2026.01.12 17:12:32 | O2: 2026.01.12 17:58:39 | P2: 55.66
A3: 3 | B3: 0 | C3: 0 | D3: buy | E3: NAS100.raw | F3: 25772.636 | G3: 25770.69 | H3: -1.95 | I3: 0 | J3: 0 | L3: 0 | N3: 2026.01.12 17:26:30 | O3: 2026.01.12 17:58:39 | P3: -1.95
A4: 4 | B4: 0 | C4: 0 | D4: buy | E4: NAS100.raw | F4: 25755.075 | G4: 25770.69 | H4: 15.61 | I4: 0 | J4: 0 | L4: 1 | N4: 2026.01.12 17:32:21 | O4: 2026.01.12 17:58:39 | P4: 15.61
A5: 5 | B5: 0 | C5: 0 | D5: buy | E5: NAS100.raw | F5: 25736.641 | G5: 25770.69 | H5: 34.05 | I5: 0 | J5: 0 | L5: 1 | N5: 2026.01.12 17:33:50 | O5: 2026.01.12 17:58:39 | P5: 34.05
A6: 6 | B6: 0 | C6: 0 | D6: buy | E6: NAS100.raw | F6: 25761.822 | G6: 25770.69 | H6: 8.87 | I6: 0 | J6: 0 | L6: 1 | N6: 2026.01.12 17:57:30 | O6: 2026.01.12 17:58:39 | P6: 8.87
A7: 7 | B7: 0 | C7: 0 | D7: buy | E7: NAS100.raw | F7: 25761.825 | G7: 25770.69 | H7: 8.86 | I7: 0 | J7: 0 | L7: 1 | N7: 2026.01.12 17:57:30 | O7: 2026.01.12 17:58:39 | P7: 8.86
A8: 8 | B8: 0 | C8: 0 | D8: 0 | E8: 0 | F8: 0 | G8: 0 | H8: 0 | I8: 0 | J8: 0 | L8: 0 | N8: 0 | O8: 0 | P8: 0
A9: 9 | B9: 0 | C9: 0 | D9: 0 | E9: 0 | F9: 0 | G9: 0 | H9: 0 | I9: 0 | J9: 0 | L9: 0 | N9: 0 | O9: 0 | P9: 0
A10: 10 | B10: 0 | C10: 0 | D10: 0 | E10: 0 | F10: 0 | G10: 0 | H10: 0 | I10: 0 | J10: 0 | L10: 0 | N10: 0 | O10: 0 | P10: 0
A11: 11 | B11: 0 | C11: 0 | D11: 0 | E11: 0 | F11: 0 | G11: 0 | H11: 0 | I11: 0 | J11: 0 | L11: 0 | N11: 0 | O11: 0 | P11: 0
A12: 12 | B12: 0 | C12: 0 | D12: 0 | E12: 0 | F12: 0 | G12: 0 | H12: 0 | I12: 0 | J12: 0 | L12: 0 | N12: 0 | O12: 0 | P12: 0
A13: 13 | B13: 0 | C13: 0 | D13: 0 | E13: 0 | F13: 0 | G13: 0 | H13: 0 | I13: 0 | J13: 0 | L13: 0 | N13: 0 | O13: 0 | P13: 0
A14: 14 | B14: 0 | C14: 0 | D14: 0 | E14: 0 | F14: 0 | G14: 0 | H14: 0 | I14: 0 | J14: 0 | L14: 0 | N14: 0 | O14: 0 | P14: 0
A15: 15 | B15: 0 | C15: 0 | D15: 0 | E15: 0 | F15: 0 | G15: 0 | H15: 0 | I15: 0 | J15: 0 | L15: 0 | N15: 0 | O15: 0 | P15: 0
A16: 16 | B16: 0 | C16: 0 | D16: 0 | E16: 0 | F16: 0 | G16: 0 | H16: 0 | I16: 0 | J16: 0 | L16: 0 | N16: 0 | O16: 0 | P16: 0
A17: 17 | B17: 0 | C17: 0 | D17: 0 | E17: 0 | F17: 0 | G17: 0 | H17: 0 | I17: 0 | J17: 0 | L17: 0 | N17: 0 | O17: 0 | P17: 0
A18: 18 | B18: 0 | C18: 0 | D18: 0 | E18: 0 | F18: 0 | G18: 0 | H18: 0 | I18: 0 | J18: 0 | L18: 0 | N18: 0 | O18: 0 | P18: 0
A19: 19 | B19: 0 | C19: 0 | D19: 0 | E19: 0 | F19: 0 | G19: 0 | H19: 0 | I19: 0 | J19: 0 | L19: 0 | N19: 0 | O19: 0 | P19: 0
... A307: 307 | B307: 0 | C307: 0 | D307: 0 | E307: 0 | F307: 0 | G307: 0 | H307: 0 | I307: 171 | J307: 0 | L307: 0 | N307: 0 | O307: 0 | P307: 0

Sheet Phase 1
A1: WINNING EDGE 1 TRADE/Day of a Loss; 2 Trades if a Win
A2: Opening Balance | C2: 100000 | D2: TT DD | E2: 10000 | F2: Risk Zone
A3: Dates | B3: Simulated Loss/Profit | C3: Risk Balance | D3: Total Expected | E3: Today's Risk | F3: 1% (If C >$10000) | G3: 0.5% (If >$7500 <$9999) | H3: 0.25% (If C < $7500) | I3: Max Risk - Daily % | J3: Max Risk - Daily $
A4: 46174 | B4: =E4*2 -> 6000 | C4: =E2+B4 -> 16000 | D4: =C2+B4 -> 106000 | E4: =C2*F4 -> 3000 | F4: 0.03 | G4: 0.02 | H4: 0.01 | I4: 0.05 | J4: =I4*C2 -> 5000
A5: =A4+1 -> 46175 | B5: =E5*2 -> 6360 | C5: =C4+B5 -> 22360 | D5: =D4+B5 -> 112360 | E5: =D4*F5 -> 3180 | F5: 0.03 | G5: 0.02 | H5: 0.01 | I5: 0.05 | J5: =I5*D4 -> 5300
A6: =A5+1 -> 46176 | B6: =E6*2 -> 6741.6 | C6: =C5+B6 -> 29101.6 | D6: =D5+B6 -> 119101.6 | E6: =D5*F6 -> 3370.8 | F6: 0.03 | G6: 0.02 | H6: 0.01 | I6: 0.05 | J6: =I6*D5 -> 5618
A7: =A6+1 -> 46177 | B7: =E7*2 -> 7146.096 | C7: =C6+B7 -> 36247.696 | D7: =D6+B7 -> 126247.7 | E7: =D6*F7 -> 3573.048 | F7: 0.03 | G7: 0.02 | H7: 0.01 | I7: 0.05 | J7: =I7*D6 -> 5955.08
A8: =A7+1 -> 46178 | B8: =E8*2 -> 7574.8618 | C8: =C7+B8 -> 43822.558 | D8: =D7+B8 -> 133822.56 | E8: =D7*F8 -> 3787.4309 | F8: 0.03 | G8: 0.02 | H8: 0.01 | I8: 0.05 | J8: =I8*D7 -> 6312.3848
A9: =A8+3 -> 46181 | B9: =E9*2 -> 8029.3535 | C9: =C8+B9 -> 51851.911 | D9: =D8+B9 -> 141851.91 | E9: =D8*F9 -> 4014.6767 | F9: 0.03 | G9: 0.02 | H9: 0.01 | I9: 0.05 | J9: =I9*D8 -> 6691.1279
A10: =A9+1 -> 46182 | B10: =E10*2 -> 8511.1147 | C10: =C9+B10 -> 60363.026 | D10: =D9+B10 -> 150363.03 | E10: =D9*F10 -> 4255.5573 | F10: 0.03 | G10: 0.02 | H10: 0.01 | I10: 0.05 | J10: =I10*D9 -> 7092.5956
A11: =A10+1 -> 46183 | B11: =E11*2 -> 9021.7816 | C11: =C10+B11 -> 69384.807 | D11: =D10+B11 -> 159384.81 | E11: =D10*F11 -> 4510.8908 | F11: 0.03 | G11: 0.02 | H11: 0.01 | I11: 0.05 | J11: =I11*D10 -> 7518.1513
A12: =A11+1 -> 46184 | B12: =E12*2 -> 9563.0884 | C12: =C11+B12 -> 78947.896 | D12: =D11+B12 -> 168947.9 | E12: =D11*F12 -> 4781.5442 | F12: 0.03 | G12: 0.02 | H12: 0.01 | I12: 0.05 | J12: =I12*D11 -> 7969.2404
A13: =A12+1 -> 46185 | B13: =E13*2 -> 10136.874 | C13: =C12+B13 -> 89084.77 | D13: =D12+B13 -> 179084.77 | E13: =D12*F13 -> 5068.4369 | F13: 0.03 | G13: 0.02 | H13: 0.01 | I13: 0.05 | J13: =I13*D12 -> 8447.3948
A14: =A13+3 -> 46188 | B14: =E14*2 -> 10745.086 | C14: =C13+B14 -> 99829.856 | D14: =D13+B14 -> 189829.86 | E14: =D13*F14 -> 5372.5431 | F14: 0.03 | G14: 0.02 | H14: 0.01 | I14: 0.05 | J14: =I14*D13 -> 8954.2385
A15: =A14+1 -> 46189 | B15: =E15*2 -> 11389.791 | C15: =C14+B15 -> 111219.65 | D15: =D14+B15 -> 201219.65 | E15: =D14*F15 -> 5694.8957 | F15: 0.03 | G15: 0.02 | H15: 0.01 | I15: 0.05 | J15: =I15*D14 -> 9491.4928
A16: =A15+1 -> 46190 | B16: =E16*2 -> 12073.179 | C16: =C15+B16 -> 123292.83 | D16: =D15+B16 -> 213292.83 | E16: =D15*F16 -> 6036.5894 | F16: 0.03 | G16: 0.02 | H16: 0.01 | I16: 0.05 | J16: =I16*D15 -> 10060.982
A17: =A16+1 -> 46191 | B17: =E17*2 -> 12797.57 | C17: =C16+B17 -> 136090.4 | D17: =D16+B17 -> 226090.4 | E17: =D16*F17 -> 6398.7848 | F17: 0.03 | G17: 0.02 | H17: 0.01 | I17: 0.05 | J17: =I17*D16 -> 10664.641
A18: =A17+1 -> 46192 | B18: =E18*2 -> 13565.424 | C18: =C17+B18 -> 149655.82 | D18: =D17+B18 -> 239655.82 | E18: =D17*F18 -> 6782.7119 | F18: 0.03 | G18: 0.02 | H18: 0.01 | I18: 0.05 | J18: =I18*D17 -> 11304.52
A19: =A18+3 -> 46195 | B19: =E19*2 -> 14379.349 | C19: =C18+B19 -> 164035.17 | D19: =D18+B19 -> 254035.17 | E19: =D18*F19 -> 7189.6746 | F19: 0.03 | G19: 0.02 | H19: 0.01 | I19: 0.05 | J19: =I19*D18 -> 11982.791
A20: =A19+1 -> 46196 | B20: =E20*2 -> 15242.11 | C20: =C19+B20 -> 179277.28 | D20: =D19+B20 -> 269277.28 | E20: =D19*F20 -> 7621.0551 | F20: 0.03 | G20: 0.02 | H20: 0.01 | I20: 0.05 | J20: =I20*D19 -> 12701.758
A21: =A20+1 -> 46197 | B21: =E21*2 -> 16156.637 | C21: =C20+B21 -> 195433.92 | D21: =D20+B21 -> 285433.92 | E21: =D20*F21 -> 8078.3184 | F21: 0.03 | G21: 0.02 | H21: 0.01 | I21: 0.05 | J21: =I21*D20 -> 13463.864
A22: =A21+1 -> 46198 | B22: =E22*2 -> 17126.035 | C22: =C21+B22 -> 212559.95 | D22: =D21+B22 -> 302559.95 | E22: =D21*F22 -> 8563.0175 | F22: 0.03 | G22: 0.02 | H22: 0.01 | I22: 0.05 | J22: =I22*D21 -> 14271.696
A23: =A22+1 -> 46199 | B23: =E23*2 -> 18153.597 | C23: =C22+B23 -> 230713.55 | D23: =D22+B23 -> 320713.55 | E23: =D22*F23 -> 9076.7985 | F23: 0.03 | G23: 0.02 | H23: 0.01 | I23: 0.05 | J23: =I23*D22 -> 15127.998
A24: =A23+3 -> 46202 | B24: =E24*2 -> 19242.813 | C24: =C23+B24 -> 249956.36 | D24: =D23+B24 -> 339956.36 | E24: =D23*F24 -> 9621.4064 | F24: 0.03 | G24: 0.02 | H24: 0.01 | I24: 0.05 | J24: =I24*D23 -> 16035.677
A25: =A24+1 -> 46203 | B25: =E25*2 -> 20397.382 | C25: =C24+B25 -> 270353.74 | D25: =D24+B25 -> 360353.74 | E25: =D24*F25 -> 10198.691 | F25: 0.03 | G25: 0.02 | H25: 0.01 | I25: 0.05 | J25: =I25*D24 -> 16997.818

Sheet GOALS
A1: Goals 2027 | B1: Target | C1: Amount/Year Ksh | D1: Amount/Year $ | E1: Bal Months | F1: Amount/Month | G1: Amount/Day | I1: Month | J1: June | K1: Week 1 | L1: July | M1: August | N1: September | O1: October | P1: November | Q1: December | R1: Total | T1: COUNT DOWN
A2: Move to a 2 bedrom house | B2: 46357 | C2: =30000*12 -> 360000 | D2: =C2/130 -> 2769.2308 | E2: 7 | F2: =D2/7*1.2 -> 474.72527 | G2: =F2/20 -> 23.736264 | I2: Account Size | J2: 10000 | K2: Pass Phase 1 | L2: =J2+10000 -> 20000 | M2: =L2+10000 -> 30000 | N2: =M2+10000 -> 40000 | O2: =N2+10000 -> 50000 | P2: =O2+10000 -> 60000 | Q2: =P2+10000 -> 70000 | R2: =Q2 -> 70000 | T2: 46387 | U2: =T2-TODAY() -> 216
A3: Monthly Expenses | B3: 46357 | C3: =50000*12 -> 600000 | D3: =C3/130 -> 4615.3846 | E3: 7 | F3: =D3/7*1.2 -> 791.20879 | G3: =F3/20 -> 39.56044 | I3: Target/Month | J3: =F2 -> 474.72527 | K3: Week 2 | L3: =L2*J5 -> 949.45055 | M3: =M2*L5 -> 1424.1758 | N3: =N2*M5 -> 1898.9011 | O3: =O2*N5 -> 2373.6264 | P3: =P2*O5 -> 2848.3516 | Q3: =Q2*P5 -> 3323.0769 | R3: =SUM(J3:Q3)*0.8 -> 10633.846 | S3: =R3-D4 -> 3249.2308
A4: Total | C4: =SUM(C2:C3) -> 960000 | D4: =SUM(D2:D3) -> 7384.6154 | F4: =SUM(F2:F3) -> 1265.9341 | G4: =SUM(G2:G3) -> 63.296703 | I4: Target/Day | J4: =J3/10 -> 47.472527 | K4: =K3/10 -> #VALUE! | L4: =L3/10 -> 94.945055 | M4: =M3/10 -> 142.41758 | N4: =N3/10 -> 189.89011 | O4: =O3/10 -> 237.36264 | P4: =P3/10 -> 284.83516 | Q4: =Q3/10 -> 332.30769
A5: MONTHLY TRADING MODEL | I5: % Target | J5: =J3/J2 -> 0.047472527 | K5: Week 3 - $237 | L5: =L3/L2 -> 0.047472527 | M5: =M3/M2 -> 0.047472527 | N5: =N3/N2 -> 0.047472527 | O5: =O3/O2 -> 0.047472527 | P5: =P3/P2 -> 0.047472527 | Q5: =Q3/Q2 -> 0.047472527
A6: Week 1 - 2 | B6: Trade to Pass Phase 1 and 2 | I6: Risk % Ideal/Day | J6: =J4/J2 -> 0.0047472527 | K6: Earn on Funded 50% | L6: =L4/L2 -> 0.0047472527 | M6: =M4/M2 -> 0.0047472527 | N6: =N4/N2 -> 0.0047472527 | O6: =O4/O2 -> 0.0047472527 | P6: =P4/P2 -> 0.0047472527 | Q6: =Q4/Q2 -> 0.0047472527
A7: Week 3 - 4 | B7: Trade to earn from the Funded Account | I7: Risk % Actual/Day | J7: 0.005 | K7: Week 4 - $237 | L7: 0.005 | M7: 0.005 | N7: 0.005 | O7: 0.005 | P7: 0.005 | Q7: 0.005
K8: Earn on Funded 50%
A9: Goals 2028 | B9: Target | C9: Amount/Year Ksh | D9: Amount/Year $ | E9: Bal Months | F9: Amount/Month | G9: Amount/Day | I9: Month | J9: January | L9: February | M9: March | N9: April | O9: May | P9: June | Q9: July | R9: August | S9: September | T9: October | U9: November | V9: December | Y9: COUNT DOWN
A10: Move to a 3 bedrom house | B10: 46722 | C10: =40000*12 -> 480000 | D10: =C10/130 -> 3692.3077 | E10: 12 | F10: =D10/E10*1.2 -> 369.23077 | G10: =F10/20 -> 18.461538 | I10: Account Size | J10: =Q2+10000 -> 80000 | L10: =J10+10000 -> 90000 | M10: =L10+10000 -> 100000 | N10: =M10+10000 -> 110000 | O10: =N10+10000 -> 120000 | P10: =O10+10000 -> 130000 | Q10: =P10+10000 -> 140000 | R10: =Q10+10000 -> 150000 | S10: =R10+10000 -> 160000 | T10: =S10+10000 -> 170000 | ... V10: =U10+10000 -> 190000 | W10: =V10 -> 190000 | Y10: 46752 | Z10: =Y10-TODAY() -> 581
A11: Monthly Expenses | B11: =B10 -> 46722 | C11: =60000*12 -> 720000 | D11: =C11/130 -> 5538.4615 | E11: 12 | F11: =D11/E11*1.2 -> 553.84615 | G11: =F11/20 -> 27.692308 | I11: Target/Month | J11: =J10*J13 -> 3797.8022 | L11: =L10*L13 -> 4272.5275 | M11: =M10*M13 -> 4747.2527 | N11: =N10*N13 -> 5221.978 | O11: =O10*O13 -> 5696.7033 | P11: =P10*P13 -> 6171.4286 | Q11: =Q10*Q13 -> 6646.1538 | R11: =R10*R13 -> 7120.8791 | S11: =S10*S13 -> 7595.6044 | ... V11: =V10*V13 -> 9019.7802 | W11: =SUM(J11:V11)*0.8 -> 61524.396 | X11: =W11-D13 -> 32678.242
A12: Buy New Car - 7 seater | B12: =B11 -> 46722 | C12: 2550000 | D12: =C12/130 -> 19615.385 | E12: 12 | F12: =D12/E12*1.2 -> 1961.5385 | G12: =F12/20 -> 98.076923 | I12: Target/Day | J12: =J11/20 -> 189.89011 | L12: =L11/20 -> 213.62637 | M12: =M11/20 -> 237.36264 | N12: =N11/20 -> 261.0989 | O12: =O11/20 -> 284.83516 | P12: =P11/20 -> 308.57143 | Q12: =Q11/20 -> 332.30769 | R12: =R11/20 -> 356.04396 | S12: =S11/20 -> 379.78022 | ... V12: =V11/20 -> 450.98901
A13: Total | C13: =SUM(C10:C12) -> 3750000 | D13: =SUM(D10:D12) -> 28846.154 | F13: =SUM(F10:F12) -> 2884.6154 | G13: =SUM(G10:G12) -> 144.23077 | I13: % Target | J13: =J5 -> 0.047472527 | L13: =J13 -> 0.047472527 | M13: =L13 -> 0.047472527 | N13: =M13 -> 0.047472527 | O13: =N13 -> 0.047472527 | P13: =O13 -> 0.047472527 | Q13: =P13 -> 0.047472527 | R13: =Q13 -> 0.047472527 | S13: =R13 -> 0.047472527 | T13: =S13 -> 0.047472527 | ... V13: =U13 -> 0.047472527
I14: Risk % Ideal/Day | J14: =J12/J10 -> 0.0023736264 | L14: =L12/L10 -> 0.0023736264 | M14: =M12/M10 -> 0.0023736264 | N14: =N12/N10 -> 0.0023736264 | O14: =O12/O10 -> 0.0023736264 | P14: =P12/P10 -> 0.0023736264 | Q14: =Q12/Q10 -> 0.0023736264 | R14: =R12/R10 -> 0.0023736264 | S14: =S12/S10 -> 0.0023736264 | ... V14: =V12/V10 -> 0.0023736264
I15: Risk % Actual/Day | J15: 0.005 | L15: 0.005 | M15: 0.005 | N15: 0.005 | O15: 0.005 | P15: 0.005 | Q15: 0.005 | R15: 0.005 | S15: 0.005 | T15: 0.005 | U15: 0.005 | V15: 0.005
A17: Goals 2029 | B17: Target | C17: Amount/Year Ksh | D17: Amount/Year $ | E17: Bal Months | F17: Amount/Month | G17: Amount/Day | I17: Month | J17: January | L17: February | M17: March | N17: April | O17: May | P17: June | Q17: July | R17: August | S17: September | T17: October | U17: November | V17: December | Y17: COUNT DOWN
A18: =A10 -> Move to a 3 bedrom house | B18: 47088 | C18: =40000*12 -> 480000 | D18: =C18/130 -> 3692.3077 | E18: 12 | F18: =D18/E18*1.2 -> 369.23077 | G18: =F18/20 -> 18.461538 | I18: Account Size | J18: =V10+10000 -> 200000 | L18: =J18+10000 -> 210000 | M18: =L18+10000 -> 220000 | N18: =M18+10000 -> 230000 | O18: =N18+10000 -> 240000 | P18: =O18+10000 -> 250000 | Q18: =P18+10000 -> 260000 | R18: =Q18+10000 -> 270000 | S18: =R18+10000 -> 280000 | T18: =S18+10000 -> 290000 | ... V18: =U18+10000 -> 310000 | W18: =V18 -> 310000 | Y18: 47118 | Z18: =Y18-TODAY() -> 947
A19: Monthly Expenses | B19: =B18 -> 47088 | C19: =100000*12 -> 1200000 | D19: =C19/130 -> 9230.7692 | E19: 12 | F19: =D19/E19*1.2 -> 923.07692 | G19: =F19/20 -> 46.153846 | I19: Target/Month | J19: =J18*J21 -> 9494.5055 | L19: =L18*L21 -> 9969.2308 | M19: =M18*M21 -> 10443.956 | N19: =N18*N21 -> 10918.681 | O19: =O18*O21 -> 11393.407 | P19: =P18*P21 -> 11868.132 | Q19: =Q18*Q21 -> 12342.857 | R19: =R18*R21 -> 12817.582 | S19: =S18*S21 -> 13292.308 | ... V19: =V18*V21 -> 14716.484 | W19: =SUM(J19:V19)*0.8 -> 116212.75 | X19: =W19-D21 -> 80212.747
A20: Buy Settlement Land | B20: =B19 -> 47088 | C20: 3000000 | D20: =C20/130 -> 23076.923 | E20: 12 | F20: =D20/E20*1.2 -> 2307.6923 | G20: =F20/20 -> 115.38462 | I20: Target/Day | J20: =J19/20 -> 474.72527 | L20: =L19/20 -> 498.46154 | M20: =M19/20 -> 522.1978 | N20: =N19/20 -> 545.93407 | O20: =O19/20 -> 569.67033 | P20: =P19/20 -> 593.40659 | Q20: =Q19/20 -> 617.14286 | R20: =R19/20 -> 640.87912 | S20: =S19/20 -> 664.61538 | ... V20: =V19/20 -> 735.82418
A21: Total | C21: =SUM(C18:C20) -> 4680000 | D21: =SUM(D18:D20) -> 36000 | F21: =SUM(F18:F20) -> 3600 | G21: =SUM(G18:G20) -> 180 | I21: % Target | J21: =J13 -> 0.047472527 | L21: =J21 -> 0.047472527 | M21: =L21 -> 0.047472527 | N21: =L21 -> 0.047472527 | O21: =M21 -> 0.047472527 | P21: =N21 -> 0.047472527 | Q21: =O21 -> 0.047472527 | R21: =P21 -> 0.047472527 | S21: =Q21 -> 0.047472527 | T21: =R21 -> 0.047472527 | U21: =S21 -> 0.047472527 | V21: =T21 -> 0.047472527
I22: Risk % Ideal/Day | J22: =J20/J18 -> 0.0023736264 | L22: =L20/L18 -> 0.0023736264 | M22: =M20/M18 -> 0.0023736264 | N22: =N20/N18 -> 0.0023736264 | O22: =O20/O18 -> 0.0023736264 | P22: =P20/P18 -> 0.0023736264 | Q22: =Q20/Q18 -> 0.0023736264 | R22: =R20/R18 -> 0.0023736264 | S22: =S20/S18 -> 0.0023736264 | ... V22: =V20/V18 -> 0.0023736264
I23: Risk % Actual/Day | J23: 0.005 | L23: 0.005 | M23: 0.005 | N23: 0.005 | O23: 0.005 | P23: 0.005 | Q23: 0.005 | R23: 0.005 | S23: 0.005 | T23: 0.005 | U23: 0.005 | V23: 0.005
A25: Goals 2030 | B25: Target | C25: Amount/Year Ksh | D25: Amount/Year $ | E25: Bal Months | F25: Amount/Month | G25: Amount/Day | I25: Month | J25: January | L25: February | M25: March | N25: April | O25: May | P25: June | Q25: July | R25: August | S25: September | T25: October | U25: November | V25: December
A26: Move to a 2 bedrom house | B26: 47453 | C26: =30000*12 -> 360000 | D26: =C26/130 -> 2769.2308 | E26: 12 | F26: =D26/E26*1.2 -> 276.92308 | G26: =F26/20 -> 13.846154 | I26: Account Size | J26: =V18+10000 -> 320000 | L26: =J26+10000 -> 330000 | M26: =L26+10000 -> 340000 | N26: =M26+10000 -> 350000 | O26: =N26+10000 -> 360000 | P26: =O26+10000 -> 370000 | Q26: =P26+10000 -> 380000 | R26: =Q26+10000 -> 390000 | S26: =R26+10000 -> 400000 | T26: =S26 -> 400000 | U26: =T26 -> 400000 | V26: =U26 -> 400000 | W26: =V26 -> 400000 | Y26: COUNT DOWN
A27: Monthly Expenses | B27: =B26 -> 47453 | C27: =100000*12 -> 1200000 | D27: =C27/130 -> 9230.7692 | E27: 12 | F27: =D27/E27*1.2 -> 923.07692 | G27: =F27/20 -> 46.153846 | I27: Target/Month | J27: =J26*J29 -> 15191.209 | L27: =L26*L29 -> 15665.934 | M27: =M26*M29 -> 16140.659 | N27: =N26*N29 -> 16615.385 | O27: =O26*O29 -> 17090.11 | P27: =P26*P29 -> 17564.835 | Q27: =Q26*Q29 -> 18039.56 | R27: =R26*R29 -> 18514.286 | S27: =S26*S29 -> 18989.011 | ... V27: =V26*V29 -> 18989.011 | W27: =SUM(J27:V27)*0.8 -> 168622.42 | X27: =W27-D29 -> 125853.19 | Y27: 47483 | Z27: =Y27-TODAY() -> 1312
A28: Build Dream Home | B28: =B27 -> 47453 | C28: 4000000 | D28: =C28/130 -> 30769.231 | E28: 12 | F28: =D28/E28*1.2 -> 3076.9231 | G28: =F28/20 -> 153.84615 | I28: Target/Day | J28: =J27/20 -> 759.56044 | L28: =L27/20 -> 783.2967 | M28: =M27/20 -> 807.03297 | N28: =N27/20 -> 830.76923 | O28: =O27/20 -> 854.50549 | P28: =P27/20 -> 878.24176 | Q28: =Q27/20 -> 901.97802 | R28: =R27/20 -> 925.71429 | S28: =S27/20 -> 949.45055 | ... V28: =V27/20 -> 949.45055
A29: Total | C29: =SUM(C26:C28) -> 5560000 | D29: =SUM(D26:D28) -> 42769.231 | F29: =SUM(F26:F28) -> 4276.9231 | G29: =SUM(G26:G28) -> 213.84615 | I29: % Target | J29: =J21 -> 0.047472527 | L29: =J29 -> 0.047472527 | M29: =L29 -> 0.047472527 | N29: =M29 -> 0.047472527 | O29: =N29 -> 0.047472527 | P29: =O29 -> 0.047472527 | Q29: =P29 -> 0.047472527 | R29: =Q29 -> 0.047472527 | S29: =R29 -> 0.047472527 | T29: =S29 -> 0.047472527 | ... V29: =U29 -> 0.047472527
I30: Risk % Ideal/Day | J30: =J28/J26 -> 0.0023736264 | L30: =L28/L26 -> 0.0023736264 | M30: =M28/M26 -> 0.0023736264 | N30: =N28/N26 -> 0.0023736264 | O30: =O28/O26 -> 0.0023736264 | P30: =P28/P26 -> 0.0023736264 | Q30: =Q28/Q26 -> 0.0023736264 | R30: =R28/R26 -> 0.0023736264 | S30: =S28/S26 -> 0.0023736264 | ... V30: =V28/V26 -> 0.0023736264
I31: Risk % Actual/Day | J31: 0.005 | L31: 0.005 | M31: 0.005 | N31: 0.005 | O31: 0.005 | P31: 0.005 | Q31: 0.005 | R31: 0.005 | S31: 0.005 | T31: 0.005 | U31: 0.005 | V31: 0.005

Sheet Compounding bot
B1: Opening Balance | D1: 10000
A2: ID | C2: Prior Day Score | D2: Top Up | E2: Today's Target | F2: Total | G2: Todays Gross profits | H2: Max Profit | I2: Expected $ | J2: Expected Ksh | K2: Withdrawable $ | L2: Withdrawable Ksh
A4: bot1 | B4: 46082 | E4: =D1*2.4% -> 240 | F4: =D1+E4 -> 10240 | H4: =(10000)*2.4% -> 240 | J4: =I4*128 -> 0 | K4: =G4-10000-200 -> -10200 | L4: =K4*128 -> -1305600
A5: bot2 | B5: =B4+1 -> 46083 | C5: =E4 -> 240 | D5: =D4 -> 0 | E5: =C5+D5 -> 240 | F5: =F4+D5 -> 10240 | H5: =(F5-10000)*2.4 -> 576 | I5: =F5-$D$1-200 -> 40 | J5: =I5*128 -> 5120 | K5: =G5-10000-200 -> -10200 | L5: =K5*128 -> -1305600
A6: bot3 | B6: =B5+1 -> 46084 | C6: =E5 -> 240 | D6: =D5 -> 0 | E6: =C6+D6 -> 240 | F6: =F5+D6 -> 10240 | H6: =(F6-10000)*2.4 -> 576 | I6: =F6-$D$1-200 -> 40 | J6: =I6*128 -> 5120 | K6: =G6-10000-200 -> -10200 | L6: =K6*128 -> -1305600
A7: bot4 | B7: =B6+1 -> 46085 | C7: =E6 -> 240 | D7: =D6 -> 0 | E7: =C7+D7 -> 240 | F7: =F6+D7 -> 10240 | H7: =(F7-10000)*2.4 -> 576 | I7: =F7-$D$1-200 -> 40 | J7: =I7*128 -> 5120 | K7: =G7-10000-200 -> -10200 | L7: =K7*128 -> -1305600
A8: bot5 | B8: =B7+1 -> 46086 | C8: =E7 -> 240 | D8: =D7 -> 0 | E8: =C8+D8 -> 240 | F8: =F7+D8 -> 10240 | H8: =(F8-10000)*2.4 -> 576 | I8: =F8-$D$1-200 -> 40 | J8: =I8*128 -> 5120 | K8: =G8-10000-200 -> -10200 | L8: =K8*128 -> -1305600
A9: bot6 | B9: =B8+1 -> 46087 | C9: =E8 -> 240 | D9: =D8 -> 0 | E9: =C9+D9 -> 240 | F9: =F8+D9 -> 10240 | H9: =(F9-10000)*2.4 -> 576 | I9: =F9-$D$1-200 -> 40 | J9: =I9*128 -> 5120 | K9: =G9-10000-200 -> -10200 | L9: =K9*128 -> -1305600
A10: bot7 | B10: =B9+1 -> 46088 | C10: =E9 -> 240 | D10: =D9 -> 0 | E10: =C10+D10 -> 240 | F10: =F9+D10 -> 10240 | H10: =(F10-10000)*2.4 -> 576 | I10: =F10-$D$1-200 -> 40 | J10: =I10*128 -> 5120 | K10: =G10-10000-200 -> -10200 | L10: =K10*128 -> -1305600
A11: bot8 | B11: =B10+1 -> 46089 | C11: =E10 -> 240 | D11: =D10 -> 0 | E11: =C11+D11 -> 240 | F11: =F10+D11 -> 10240 | H11: =(F11-10000)*2.4 -> 576 | I11: =F11-$D$1-200 -> 40 | J11: =I11*128 -> 5120 | K11: =G11-10000-200 -> -10200 | L11: =K11*128 -> -1305600
A12: bot9 | B12: =B11+1 -> 46090 | C12: =E11 -> 240 | D12: =D11 -> 0 | E12: =C12+D12 -> 240 | F12: =F11+D12 -> 10240 | H12: =(F12-10000)*2.4 -> 576 | I12: =F12-$D$1-200 -> 40 | J12: =I12*128 -> 5120 | K12: =G12-10000-200 -> -10200 | L12: =K12*128 -> -1305600
A13: bot10 | B13: =B12+1 -> 46091 | C13: =E12 -> 240 | D13: =D12 -> 0 | E13: =C13+D13 -> 240 | F13: =F12+D13 -> 10240 | H13: =(F13-10000)*2.4 -> 576 | I13: =F13-$D$1-200 -> 40 | J13: =I13*128 -> 5120 | K13: =G13-10000-200 -> -10200 | L13: =K13*128 -> -1305600

Sheet Compounding 2026
B1: Opening Balance | D1: 10000
A2: ID | C2: Prior Day Score | D2: Top Up | E2: Today's Target | F2: Total | G2: Todays Gross profits | H2: Expected $ | I2: Expected Ksh | J2: Withdrawable $ | K2: Withdrawable Ksh
A3: Challenge 2 | B3: 46024 | C3: =D3 -> 150 | D3: 150 | E3: =C3 -> 150 | F3: =D1+D3 -> 10150
A4: Challenge 3 | B4: =B3+3 -> 46027 | C4: =E3 -> 150 | D4: =D3 -> 150 | E4: =C4+D4 -> 300 | F4: =F3+D4 -> 10300
A5: Challenge 4 | B5: =B4+1 -> 46028 | C5: =E4 -> 300 | D5: =D4 -> 150 | E5: =C5+D5 -> 450 | F5: =F4+D5 -> 10450
A6: Challenge 5 | B6: =B5+1 -> 46029 | C6: =E5 -> 450 | D6: =D5 -> 150 | E6: =C6+D6 -> 600 | F6: =F5+D6 -> 10600
A7: Challenge 6 | B7: =B6+1 -> 46030 | C7: =E6 -> 600 | D7: =D6 -> 150 | E7: =C7+D7 -> 750 | F7: =F6+D7 -> 10750
A8: Challenge 7 | B8: =B7+1 -> 46031 | C8: =E7 -> 750 | D8: =D7 -> 150 | E8: =C8+D8 -> 900 | F8: =F7+D8 -> 10900
A9: Challenge 8 | B9: =B8+3 -> 46034 | C9: =E8 -> 900 | D9: =D8 -> 150 | E9: =C9+D9 -> 1050 | F9: =F8+D9 -> 11050
A10: Verification 1 | B10: =B9+1 -> 46035 | C10: =E9 -> 1050 | D10: =D9 -> 150 | E10: =D10 -> 150 | F10: =D10+D1 -> 10150
A11: Verification 2 | B11: =B10+1 -> 46036 | C11: =E10 -> 150 | D11: =D10 -> 150 | E11: =C11+D11 -> 300 | F11: =F10+D11 -> 10300
A12: Verification 3 | B12: =B11+1 -> 46037 | C12: =E11 -> 300 | D12: =D11 -> 150 | E12: =C12+D12 -> 450 | F12: =F11+D12 -> 10450
A13: Verification 4 | B13: =B12+1 -> 46038 | C13: =E12 -> 450 | D13: =D12 -> 150 | E13: =C13+D13 -> 600 | F13: =F12+D13 -> 10600
A14: REVIIEW DAY | B14: =B13+3 -> 46041
A15: Funded 1 | B15: =B14+1 -> 46042 | C15: =E14 -> 0 | D15: =D12 -> 150 | E15: =C15+D15 -> 150 | F15: =$D$1+D15 -> 10150
A16: Funded 2 | B16: =B15+1 -> 46043 | C16: =D15 -> 150 | D16: =D13 -> 150 | E16: =C16+D16 -> 300 | F16: =F15+D16 -> 10300 | H16: =F16-$D$1-200 -> 100 | I16: =H16*128 -> 12800
A17: Funded 3 | B17: =B16+1 -> 46044 | C17: =E16 -> 300 | D17: =D15 -> 150 | E17: =C17+D17 -> 450 | F17: =F16+D17 -> 10450 | H17: =F17-$D$1-200 -> 250 | I17: =H17*128 -> 32000 | J17: =G17-10000-200 -> -10200 | K17: =J17*128 -> -1305600
A18: Funded 4 | B18: =B17+1 -> 46045 | C18: =E17 -> 450 | D18: =D17 -> 150 | E18: =C18+D18 -> 600 | F18: =F17+D18 -> 10600 | H18: =F18-$D$1-200 -> 400 | I18: =H18*128 -> 51200 | J18: =G18-10000-200 -> -10200 | K18: =J18*128 -> -1305600
A19: Funded 5 | B19: =B18+3 -> 46048 | C19: =E18 -> 600 | D19: =D18 -> 150 | E19: =C19+D19 -> 750 | F19: =F18+D19 -> 10750 | H19: =F19-$D$1-200 -> 550 | I19: =H19*128 -> 70400 | J19: =G19-10000-200 -> -10200 | K19: =J19*128 -> -1305600
A20: Funded 6 | B20: =B19+1 -> 46049 | C20: =E19 -> 750 | D20: =D19 -> 150 | E20: =C20+D20 -> 900 | F20: =F19+D20 -> 10900 | H20: =F20-$D$1-200 -> 700 | I20: =H20*128 -> 89600 | J20: =G20-10000-200 -> -10200 | K20: =J20*128 -> -1305600
A21: Funded 7 | B21: =B20+1 -> 46050 | C21: =E20 -> 900 | D21: =D20 -> 150 | E21: =C21+D21 -> 1050 | F21: =F20+D21 -> 11050 | H21: =F21-$D$1-200 -> 850 | I21: =H21*128 -> 108800 | J21: =G21-10000-200 -> -10200 | K21: =J21*128 -> -1305600
A22: Funded 8 | B22: =B21+1 -> 46051 | C22: =E21 -> 1050 | D22: =D21 -> 150 | E22: =C22+D22 -> 1200 | F22: =F21+D22 -> 11200 | H22: =F22-$D$1-200 -> 1000 | I22: =H22*128 -> 128000 | J22: =G22-10000-200 -> -10200 | K22: =J22*128 -> -1305600
A23: Funded 7 Request Payout | B23: =B22+1 -> 46052 | C23: =E22 -> 1200 | D23: =D22 -> 150 | E23: =C23+D23 -> 1350 | F23: =F22+D23 -> 11350 | H23: =F23-$D$1-200 -> 1150 | I23: =H23*128 -> 147200 | J23: =G23-10000-200 -> -10200 | K23: =J23*128 -> -1305600
A24: 10K Account | B24: + | C24: 25K Account | D24: Bot FTMO | E24: 10K Account | M24: 10000 | N24: 150
A25: Withdraw 1 | B25: =B23+3 -> 46055 | C25: 0 | D25: 0 | E25: 0 | F25: 0 | H25: 10K Yields | I25: =H25*128 -> #VALUE! | K25: =J25*128 -> 0 | M25: 35000 | N25: =(M25*N24)/M24 -> 525
A26: Withdraw 2 | B26: =B25+1 -> 46056 | C26: =E25 -> 0 | D26: 0 | E26: =C26+D26 -> 0 | F26: =F25+D26 -> 0 | H26: 0 | I26: =H26*128 -> 0 | K26: =J26*128 -> 0
A27: Challenge 2 | B27: =B26+1 -> 46057 | C27: =E26 -> 0 | D27: =N25 -> 525 | E27: =C27+D27-150 -> 375 | F27: =F26+D27+D1 -> 10525 | H27: 150
A28: Challenge 3 | B28: =B27+1 -> 46058 | C28: =E27 -> 375 | D28: =D27 -> 525 | E28: =C28+D28-150 -> 750 | F28: =F27+D28 -> 11050 | H28: =H27+150 -> 300
A29: Challenge 4 | B29: =B28+1 -> 46059 | C29: =E28 -> 750 | D29: =D28 -> 525 | E29: =C29+D29-150 -> 1125 | F29: =F28+D29 -> 11575 | H29: =H28+150 -> 450
A30: Challenge 5 | B30: =B29+3 -> 46062 | C30: =E29 -> 1125 | D30: =D29 -> 525 | E30: =C30+D30-150 -> 1500 | F30: =F29+D30 -> 12100 | H30: =H29+150 -> 600
A31: Challenge 6 | B31: =B30+1 -> 46063 | C31: =E30 -> 1500 | D31: =D30 -> 525 | E31: =C31+D31-150 -> 1875 | F31: =F30+D31 -> 12625 | H31: =H30+150 -> 750
A32: Challenge 7 | B32: =B31+1 -> 46064 | C32: =E31 -> 1875 | D32: =D31 -> 525 | E32: =C32+D32-150 -> 2250 | F32: =F31+D32 -> 13150 | H32: =H31+150 -> 900
A33: Challenge 8 | B33: =B32+1 -> 46065 | C33: =E32 -> 2250 | D33: =D32 -> 525 | E33: =C33+D33-150 -> 2625 | F33: =F32+D33 -> 13675 | H33: =H32+150 -> 1050
A34: Verification 1 | B34: =B33+1 -> 46066 | C34: 0 | D34: =D33 -> 525 | E34: =C34+D34-150 -> 375 | F34: =F33+D34 -> 14200 | H34: =H33+150 -> 1200
A35: Verification 2 | B35: =B34+3 -> 46069 | C35: =E34 -> 375 | D35: =D34 -> 525 | E35: =E34+E34 -> 750 | F35: =D35+D1 -> 10525 | H35: =H34+150 -> 1350
A36: Verification 3 | B36: =B35+1 -> 46070 | C36: =E35 -> 750 | D36: =D35 -> 525 | E36: =C36+D36-150 -> 1125 | F36: =F35+D36 -> 11050 | H36: =H35+150 -> 1500
A37: Verification 4 | B37: =B36+1 -> 46071 | C37: =E36 -> 1125 | D37: =D36 -> 525 | E37: =C37+D37-150 -> 1500 | F37: =F36+D37 -> 11575 | H37: =H36+150 -> 1650
A38: REVIIEW DAY | B38: =B37+1 -> 46072 | C38: =E37 -> 1500 | D38: =D37 -> 525 | E38: =C38+D38-150 -> 1875 | F38: =F37+D38 -> 12100 | H38: =H37+150 -> 1800 | I38: =H38*128 -> 230400
A39: Funded 13 | B39: =B38+1 -> 46073 | C39: 0 | D39: =D38 -> 525 | E39: =D39 -> 525 | F39: =D1+D39 -> 10525 | H39: =D39+H38 -> 2325 | I39: =H39*128 -> 297600 | J39: =G39-10000-200 -> -10200 | K39: =J39*128 -> -1305600
A40: Funded 14 | B40: =B39+3 -> 46076 | C40: =E39 -> 525 | D40: =D39 -> 525 | E40: =C40+D40 -> 1050 | F40: =F39+D40 -> 11050 | H40: =H39+D40 -> 2850 | I40: =H40*128 -> 364800 | J40: =G40-10000-200 -> -10200 | K40: =J40*128 -> -1305600
...
